Workbook

Sheet הנחות
A1: הנחות וקבועים — עדכנו את התאים הצהובים בלבד
A3: פרמטר | B3: ערך | C3: הערות
A4: מחיר למ"ר לפני מע"מ (לפי המכרז) | B4: 15022 | C4: נתון מהמשתמש — מכרז מחיר מטרה
A5: מקדם מרפסת לחישוב המחיר | B5: 0.3 | C5: הנחת עבודה מקובלת במכרזי מחיר מטרה/למשתכן — לאמת מול נספח התמורה בחוזה!
A6: מע"מ | B6: 0.18 | C6: שיעור מע"מ נכון ל-2026 — לעדכן אם ישתנה עד החתימה
A7: שיעור הנחה | B7: 0.2 | C7: הנמוך מבין 20% מהמחיר או תקרת ההנחה
A8: תקרת הנחה | B8: 300000 | C8: נתון מהמשתמש
A9: מחיר שוק משוער למ"ר (כולל מע"מ) | B9: 24000 | C9: הערכת מקום ראשונית לדירה חדשה בנוף צמרת/פ"ת — חובה לעדכן לפי עסקאות אמת/שמאות
A10: מקדם מרפסת בשווי שוק | B10: 0.5 | C10: הנחת עבודה לשווי מרפסת בשוק החופשי
A12: הערות חשובות:
A13: 1. על המחיר החוזי תתווסף הצמדה למדד תשומות הבנייה (לא מגולמת כאן) — ההצמדה חלה בדרך כלל על יתרת התשלומים.
A14: 2. הנתונים חולצו אוטומטית מקובץ ה-DWFX של תכניות המכר (גיליון R18367-X-XX-DP-A-001, Revit 2024, פרויקט "אדרת בצמרת - סירקין", מגרש 201).
A15: 3. שטחי מרפסות נלקחו מתוויות "מרפסת שמש" בתכניות, ואומתו פר טיפוס דירה על פני כל הקומות.
A16: 4. "פונה לפארק": הפארק הציבורי גובל במגרש ממזרח. ההנחה: בניינים 2-3 בצד המזרחי של המגרש — כיוון מזרח בהם פתוח לפארק; בבניין 1 מזרח מוסתר חלקית. לאמת מול תשריט הפיתוח!
A17: 5. בקומה טיפוסית 2-3 מוצגת תכנית אחת לשתי הקומות; מספרי הדירות בקומה 3 = קומה 2 + 5 (אומת מול טבלאות התכנית).
A18: 6. דירות 3G (בניין 3, דירות 1-2) כוללות חצר פרטית ששטחה אינו מסומן בתכנית.
A19: 7. שדה "תקרת מחיר מטרה" = הכיתוב "שייכות מחיר מטרה עד 80/110 מ"ר" המופיע בטבלת כל דירה בתכנית.

Sheet דירות מחיר מטרה
A1: בניין | B1: דירה | C1: קומה | D1: טיפוס | E1: חדרים | F1: שטח דירה (מ"ר) | G1: מרפסת שמש (מ"ר) | H1: מס' מרפסות | I1: חצר | J1: כיווני אוויר | K1: פונה לפארק | L1: תקרת מחיר מטרה (מ"ר) | M1: שטח לתמחור (מ"ר) | N1: מחיר לפני מע"מ | O1: מחיר כולל מע"מ | P1: הנחה | Q1: מחיר נטו לתשלום | R1: שווי שוק משוער | S1: רווח גולמי משוער | T1: דירוג רווח
A2: 1 | B2: 2 | C2: 1 | D2: 1A | E2: 3 | F2: 87.77 | G2: 21.67 | H2: 2 | J2: מערב - צפון | L2: 110 | M2: =F2+הנחות!$B$5*G2 -> 94.271 | N2: =ROUND(M2*הנחות!$B$4,0) -> 1416139 | O2: =ROUND(N2*(1+הנחות!$B$6),0) -> 1671044 | P2: =MIN(הנחות!$B$7*O2,הנחות!$B$8) -> 300000 | Q2: =O2-P2 -> 1371044 | R2: =ROUND(הנחות!$B$9*(F2+הנחות!$B$10*G2),0) -> 2366520 | S2: =R2-Q2 -> 995476 | T2: =RANK(S2,S$2:S$85) -> 40
A3: 1 | B3: 3 | C3: 1 | D3: 1B | E3: 4 | F3: 107.95 | G3: 11.88 | H3: 1 | J3: מזרח - צפון | K3: חלקי | L3: 110 | M3: =F3+הנחות!$B$5*G3 -> 111.514 | N3: =ROUND(M3*הנחות!$B$4,0) -> 1675163 | O3: =ROUND(N3*(1+הנחות!$B$6),0) -> 1976692 | P3: =MIN(הנחות!$B$7*O3,הנחות!$B$8) -> 300000 | Q3: =O3-P3 -> 1676692 | R3: =ROUND(הנחות!$B$9*(F3+הנחות!$B$10*G3),0) -> 2733360 | S3: =R3-Q3 -> 1056668 | T3: =RANK(S3,S$2:S$85) -> 27
A4: 1 | B4: 4 | C4: 1 | D4: 1C | E4: 3 | F4: 79.72 | G4: 13.6 | H4: 1 | J4: מזרח - דרום | K4: חלקי | L4: 80 | M4: =F4+הנחות!$B$5*G4 -> 83.8 | N4: =ROUND(M4*הנחות!$B$4,0) -> 1258844 | O4: =ROUND(N4*(1+הנחות!$B$6),0) -> 1485436 | P4: =MIN(הנחות!$B$7*O4,הנחות!$B$8) -> 297087.2 | Q4: =O4-P4 -> 1188348.8 | R4: =ROUND(הנחות!$B$9*(F4+הנחות!$B$10*G4),0) -> 2076480 | S4: =R4-Q4 -> 888131.2 | T4: =RANK(S4,S$2:S$85) -> 62
A5: 1 | B5: 5 | C5: 1 | D5: 1D | E5: 3 | F5: 78.78 | G5: 7.4 | H5: 1 | J5: דרום | L5: 80 | M5: =F5+הנחות!$B$5*G5 -> 81 | N5: =ROUND(M5*הנחות!$B$4,0) -> 1216782 | O5: =ROUND(N5*(1+הנחות!$B$6),0) -> 1435803 | P5: =MIN(הנחות!$B$7*O5,הנחות!$B$8) -> 287160.6 | Q5: =O5-P5 -> 1148642.4 | R5: =ROUND(הנחות!$B$9*(F5+הנחות!$B$10*G5),0) -> 1979520 | S5: =R5-Q5 -> 830877.6 | T5: =RANK(S5,S$2:S$85) -> 68
A6: 1 | B6: 6 | C6: 1 | D6: 1E | E6: 4 | F6: 109.6 | G6: 13.01 | H6: 1 | J6: מערב - דרום | L6: 110 | M6: =F6+הנחות!$B$5*G6 -> 113.503 | N6: =ROUND(M6*הנחות!$B$4,0) -> 1705042 | O6: =ROUND(N6*(1+הנחות!$B$6),0) -> 2011950 | P6: =MIN(הנחות!$B$7*O6,הנחות!$B$8) -> 300000 | Q6: =O6-P6 -> 1711950 | R6: =ROUND(הנחות!$B$9*(F6+הנחות!$B$10*G6),0) -> 2786520 | S6: =R6-Q6 -> 1074570 | T6: =RANK(S6,S$2:S$85) -> 7
A7: 1 | B7: 7 | C7: 2 | D7: 1A | E7: 3 | F7: 87.77 | G7: 21.67 | H7: 2 | J7: מערב - צפון | L7: 110 | M7: =F7+הנחות!$B$5*G7 -> 94.271 | N7: =ROUND(M7*הנחות!$B$4,0) -> 1416139 | O7: =ROUND(N7*(1+הנחות!$B$6),0) -> 1671044 | P7: =MIN(הנחות!$B$7*O7,הנחות!$B$8) -> 300000 | Q7: =O7-P7 -> 1371044 | R7: =ROUND(הנחות!$B$9*(F7+הנחות!$B$10*G7),0) -> 2366520 | S7: =R7-Q7 -> 995476 | T7: =RANK(S7,S$2:S$85) -> 40
A8: 1 | B8: 8 | C8: 2 | D8: 1B | E8: 4 | F8: 107.95 | G8: 11.88 | H8: 1 | J8: מזרח - צפון | K8: חלקי | L8: 110 | M8: =F8+הנחות!$B$5*G8 -> 111.514 | N8: =ROUND(M8*הנחות!$B$4,0) -> 1675163 | O8: =ROUND(N8*(1+הנחות!$B$6),0) -> 1976692 | P8: =MIN(הנחות!$B$7*O8,הנחות!$B$8) -> 300000 | Q8: =O8-P8 -> 1676692 | R8: =ROUND(הנחות!$B$9*(F8+הנחות!$B$10*G8),0) -> 2733360 | S8: =R8-Q8 -> 1056668 | T8: =RANK(S8,S$2:S$85) -> 27
A9: 1 | B9: 9 | C9: 2 | D9: 1C | E9: 3 | F9: 79.72 | G9: 13.6 | H9: 1 | J9: מזרח - דרום | K9: חלקי | L9: 80 | M9: =F9+הנחות!$B$5*G9 -> 83.8 | N9: =ROUND(M9*הנחות!$B$4,0) -> 1258844 | O9: =ROUND(N9*(1+הנחות!$B$6),0) -> 1485436 | P9: =MIN(הנחות!$B$7*O9,הנחות!$B$8) -> 297087.2 | Q9: =O9-P9 -> 1188348.8 | R9: =ROUND(הנחות!$B$9*(F9+הנחות!$B$10*G9),0) -> 2076480 | S9: =R9-Q9 -> 888131.2 | T9: =RANK(S9,S$2:S$85) -> 62
A10: 1 | B10: 10 | C10: 2 | D10: 1D | E10: 3 | F10: 78.78 | G10: 7.4 | H10: 1 | J10: דרום | L10: 80 | M10: =F10+הנחות!$B$5*G10 -> 81 | N10: =ROUND(M10*הנחות!$B$4,0) -> 1216782 | O10: =ROUND(N10*(1+הנחות!$B$6),0) -> 1435803 | P10: =MIN(הנחות!$B$7*O10,הנחות!$B$8) -> 287160.6 | Q10: =O10-P10 -> 1148642.4 | R10: =ROUND(הנחות!$B$9*(F10+הנחות!$B$10*G10),0) -> 1979520 | S10: =R10-Q10 -> 830877.6 | T10: =RANK(S10,S$2:S$85) -> 68
A11: 1 | B11: 11 | C11: 2 | D11: 1E | E11: 4 | F11: 109.6 | G11: 13.01 | H11: 1 | J11: מערב - דרום | L11: 110 | M11: =F11+הנחות!$B$5*G11 -> 113.503 | N11: =ROUND(M11*הנחות!$B$4,0) -> 1705042 | O11: =ROUND(N11*(1+הנחות!$B$6),0) -> 2011950 | P11: =MIN(הנחות!$B$7*O11,הנחות!$B$8) -> 300000 | Q11: =O11-P11 -> 1711950 | R11: =ROUND(הנחות!$B$9*(F11+הנחות!$B$10*G11),0) -> 2786520 | S11: =R11-Q11 -> 1074570 | T11: =RANK(S11,S$2:S$85) -> 7
A12: 1 | B12: 12 | C12: 3 | D12: 1A | E12: 3 | F12: 87.77 | G12: 21.67 | H12: 2 | J12: מערב - צפון | L12: 110 | M12: =F12+הנחות!$B$5*G12 -> 94.271 | N12: =ROUND(M12*הנחות!$B$4,0) -> 1416139 | O12: =ROUND(N12*(1+הנחות!$B$6),0) -> 1671044 | P12: =MIN(הנחות!$B$7*O12,הנחות!$B$8) -> 300000 | Q12: =O12-P12 -> 1371044 | R12: =ROUND(הנחות!$B$9*(F12+הנחות!$B$10*G12),0) -> 2366520 | S12: =R12-Q12 -> 995476 | T12: =RANK(S12,S$2:S$85) -> 40
A13: 1 | B13: 13 | C13: 3 | D13: 1B | E13: 4 | F13: 107.95 | G13: 11.88 | H13: 1 | J13: מזרח - צפון | K13: חלקי | L13: 110 | M13: =F13+הנחות!$B$5*G13 -> 111.514 | N13: =ROUND(M13*הנחות!$B$4,0) -> 1675163 | O13: =ROUND(N13*(1+הנחות!$B$6),0) -> 1976692 | P13: =MIN(הנחות!$B$7*O13,הנחות!$B$8) -> 300000 | Q13: =O13-P13 -> 1676692 | R13: =ROUND(הנחות!$B$9*(F13+הנחות!$B$10*G13),0) -> 2733360 | S13: =R13-Q13 -> 1056668 | T13: =RANK(S13,S$2:S$85) -> 27
A14: 1 | B14: 14 | C14: 3 | D14: 1C | E14: 3 | F14: 79.72 | G14: 13.6 | H14: 1 | J14: מזרח - דרום | K14: חלקי | L14: 80 | M14: =F14+הנחות!$B$5*G14 -> 83.8 | N14: =ROUND(M14*הנחות!$B$4,0) -> 1258844 | O14: =ROUND(N14*(1+הנחות!$B$6),0) -> 1485436 | P14: =MIN(הנחות!$B$7*O14,הנחות!$B$8) -> 297087.2 | Q14: =O14-P14 -> 1188348.8 | R14: =ROUND(הנחות!$B$9*(F14+הנחות!$B$10*G14),0) -> 2076480 | S14: =R14-Q14 -> 888131.2 | T14: =RANK(S14,S$2:S$85) -> 62
A15: 1 | B15: 15 | C15: 3 | D15: 1D | E15: 3 | F15: 78.78 | G15: 7.4 | H15: 1 | J15: דרום | L15: 80 | M15: =F15+הנחות!$B$5*G15 -> 81 | N15: =ROUND(M15*הנחות!$B$4,0) -> 1216782 | O15: =ROUND(N15*(1+הנחות!$B$6),0) -> 1435803 | P15: =MIN(הנחות!$B$7*O15,הנחות!$B$8) -> 287160.6 | Q15: =O15-P15 -> 1148642.4 | R15: =ROUND(הנחות!$B$9*(F15+הנחות!$B$10*G15),0) -> 1979520 | S15: =R15-Q15 -> 830877.6 | T15: =RANK(S15,S$2:S$85) -> 68
A16: 1 | B16: 16 | C16: 3 | D16: 1E | E16: 4 | F16: 109.6 | G16: 13.01 | H16: 1 | J16: מערב - דרום | L16: 110 | M16: =F16+הנחות!$B$5*G16 -> 113.503 | N16: =ROUND(M16*הנחות!$B$4,0) -> 1705042 | O16: =ROUND(N16*(1+הנחות!$B$6),0) -> 2011950 | P16: =MIN(הנחות!$B$7*O16,הנחות!$B$8) -> 300000 | Q16: =O16-P16 -> 1711950 | R16: =ROUND(הנחות!$B$9*(F16+הנחות!$B$10*G16),0) -> 2786520 | S16: =R16-Q16 -> 1074570 | T16: =RANK(S16,S$2:S$85) -> 7
A17: 1 | B17: 17 | C17: 4 | D17: 1A | E17: 3 | F17: 87.77 | G17: 21.67 | H17: 2 | J17: מערב - צפון | L17: 110 | M17: =F17+הנחות!$B$5*G17 -> 94.271 | N17: =ROUND(M17*הנחות!$B$4,0) -> 1416139 | O17: =ROUND(N17*(1+הנחות!$B$6),0) -> 1671044 | P17: =MIN(הנחות!$B$7*O17,הנחות!$B$8) -> 300000 | Q17: =O17-P17 -> 1371044 | R17: =ROUND(הנחות!$B$9*(F17+הנחות!$B$10*G17),0) -> 2366520 | S17: =R17-Q17 -> 995476 | T17: =RANK(S17,S$2:S$85) -> 40
A18: 1 | B18: 18 | C18: 4 | D18: 1B | E18: 4 | F18: 107.95 | G18: 11.88 | H18: 1 | J18: מזרח - צפון | K18: חלקי | L18: 110 | M18: =F18+הנחות!$B$5*G18 -> 111.514 | N18: =ROUND(M18*הנחות!$B$4,0) -> 1675163 | O18: =ROUND(N18*(1+הנחות!$B$6),0) -> 1976692 | P18: =MIN(הנחות!$B$7*O18,הנחות!$B$8) -> 300000 | Q18: =O18-P18 -> 1676692 | R18: =ROUND(הנחות!$B$9*(F18+הנחות!$B$10*G18),0) -> 2733360 | S18: =R18-Q18 -> 1056668 | T18: =RANK(S18,S$2:S$85) -> 27
A19: 1 | B19: 19 | C19: 4 | D19: 1C | E19: 3 | F19: 79.72 | G19: 13.6 | H19: 1 | J19: מזרח - דרום | K19: חלקי | L19: 80 | M19: =F19+הנחות!$B$5*G19 -> 83.8 | N19: =ROUND(M19*הנחות!$B$4,0) -> 1258844 | O19: =ROUND(N19*(1+הנחות!$B$6),0) -> 1485436 | P19: =MIN(הנחות!$B$7*O19,הנחות!$B$8) -> 297087.2 | Q19: =O19-P19 -> 1188348.8 | R19: =ROUND(הנחות!$B$9*(F19+הנחות!$B$10*G19),0) -> 2076480 | S19: =R19-Q19 -> 888131.2 | T19: =RANK(S19,S$2:S$85) -> 62
A20: 1 | B20: 20 | C20: 4 | D20: 1D | E20: 3 | F20: 78.78 | G20: 7.4 | H20: 1 | J20: דרום | L20: 80 | M20: =F20+הנחות!$B$5*G20 -> 81 | N20: =ROUND(M20*הנחות!$B$4,0) -> 1216782 | O20: =ROUND(N20*(1+הנחות!$B$6),0) -> 1435803 | P20: =MIN(הנחות!$B$7*O20,הנחות!$B$8) -> 287160.6 | Q20: =O20-P20 -> 1148642.4 | R20: =ROUND(הנחות!$B$9*(F20+הנחות!$B$10*G20),0) -> 1979520 | S20: =R20-Q20 -> 830877.6 | T20: =RANK(S20,S$2:S$85) -> 68
A21: 1 | B21: 21 | C21: 4 | D21: 1E | E21: 4 | F21: 109.6 | G21: 13.01 | H21: 1 | J21: מערב - דרום | L21: 110 | M21: =F21+הנחות!$B$5*G21 -> 113.503 | N21: =ROUND(M21*הנחות!$B$4,0) -> 1705042 | O21: =ROUND(N21*(1+הנחות!$B$6),0) -> 2011950 | P21: =MIN(הנחות!$B$7*O21,הנחות!$B$8) -> 300000 | Q21: =O21-P21 -> 1711950 | R21: =ROUND(הנחות!$B$9*(F21+הנחות!$B$10*G21),0) -> 2786520 | S21: =R21-Q21 -> 1074570 | T21: =RANK(S21,S$2:S$85) -> 7
A22: 1 | B22: 22 | C22: 5 | D22: 1A | E22: 3 | F22: 87.77 | G22: 21.67 | H22: 2 | J22: מערב - צפון | L22: 110 | M22: =F22+הנחות!$B$5*G22 -> 94.271 | N22: =ROUND(M22*הנחות!$B$4,0) -> 1416139 | O22: =ROUND(N22*(1+הנחות!$B$6),0) -> 1671044 | P22: =MIN(הנחות!$B$7*O22,הנחות!$B$8) -> 300000 | Q22: =O22-P22 -> 1371044 | R22: =ROUND(הנחות!$B$9*(F22+הנחות!$B$10*G22),0) -> 2366520 | S22: =R22-Q22 -> 995476 | T22: =RANK(S22,S$2:S$85) -> 40
A23: 1 | B23: 23 | C23: 5 | D23: 1B | E23: 4 | F23: 107.95 | G23: 11.88 | H23: 1 | J23: מזרח - צפון | K23: חלקי | L23: 110 | M23: =F23+הנחות!$B$5*G23 -> 111.514 | N23: =ROUND(M23*הנחות!$B$4,0) -> 1675163 | O23: =ROUND(N23*(1+הנחות!$B$6),0) -> 1976692 | P23: =MIN(הנחות!$B$7*O23,הנחות!$B$8) -> 300000 | Q23: =O23-P23 -> 1676692 | R23: =ROUND(הנחות!$B$9*(F23+הנחות!$B$10*G23),0) -> 2733360 | S23: =R23-Q23 -> 1056668 | T23: =RANK(S23,S$2:S$85) -> 27
A24: 1 | B24: 24 | C24: 5 | D24: 1C | E24: 3 | F24: 79.72 | G24: 13.6 | H24: 1 | J24: מזרח - דרום | K24: חלקי | L24: 80 | M24: =F24+הנחות!$B$5*G24 -> 83.8 | N24: =ROUND(M24*הנחות!$B$4,0) -> 1258844 | O24: =ROUND(N24*(1+הנחות!$B$6),0) -> 1485436 | P24: =MIN(הנחות!$B$7*O24,הנחות!$B$8) -> 297087.2 | Q24: =O24-P24 -> 1188348.8 | R24: =ROUND(הנחות!$B$9*(F24+הנחות!$B$10*G24),0) -> 2076480 | S24: =R24-Q24 -> 888131.2 | T24: =RANK(S24,S$2:S$85) -> 62
A25: 1 | B25: 25 | C25: 5 | D25: 1D | E25: 3 | F25: 78.78 | G25: 7.4 | H25: 1 | J25: דרום | L25: 80 | M25: =F25+הנחות!$B$5*G25 -> 81 | N25: =ROUND(M25*הנחות!$B$4,0) -> 1216782 | O25: =ROUND(N25*(1+הנחות!$B$6),0) -> 1435803 | P25: =MIN(הנחות!$B$7*O25,הנחות!$B$8) -> 287160.6 | Q25: =O25-P25 -> 1148642.4 | R25: =ROUND(הנחות!$B$9*(F25+הנחות!$B$10*G25),0) -> 1979520 | S25: =R25-Q25 -> 830877.6 | T25: =RANK(S25,S$2:S$85) -> 68
A26: 1 | B26: 26 | C26: 5 | D26: 1E | E26: 4 | F26: 109.6 | G26: 13.01 | H26: 1 | J26: מערב - דרום | L26: 110 | M26: =F26+הנחות!$B$5*G26 -> 113.503 | N26: =ROUND(M26*הנחות!$B$4,0) -> 1705042 | O26: =ROUND(N26*(1+הנחות!$B$6),0) -> 2011950 | P26: =MIN(הנחות!$B$7*O26,הנחות!$B$8) -> 300000 | Q26: =O26-P26 -> 1711950 | R26: =ROUND(הנחות!$B$9*(F26+הנחות!$B$10*G26),0) -> 2786520 | S26: =R26-Q26 -> 1074570 | T26: =RANK(S26,S$2:S$85) -> 7
A27: 1 | B27: 27 | C27: 6 | D27: 1A | E27: 3 | F27: 87.77 | G27: 21.67 | H27: 2 | J27: מערב - צפון | L27: 110 | M27: =F27+הנחות!$B$5*G27 -> 94.271 | N27: =ROUND(M27*הנחות!$B$4,0) -> 1416139 | O27: =ROUND(N27*(1+הנחות!$B$6),0) -> 1671044 | P27: =MIN(הנחות!$B$7*O27,הנחות!$B$8) -> 300000 | Q27: =O27-P27 -> 1371044 | R27: =ROUND(הנחות!$B$9*(F27+הנחות!$B$10*G27),0) -> 2366520 | S27: =R27-Q27 -> 995476 | T27: =RANK(S27,S$2:S$85) -> 40
A28: 1 | B28: 28 | C28: 6 | D28: 1B | E28: 4 | F28: 107.95 | G28: 11.88 | H28: 1 | J28: מזרח - צפון | K28: חלקי | L28: 110 | M28: =F28+הנחות!$B$5*G28 -> 111.514 | N28: =ROUND(M28*הנחות!$B$4,0) -> 1675163 | O28: =ROUND(N28*(1+הנחות!$B$6),0) -> 1976692 | P28: =MIN(הנחות!$B$7*O28,הנחות!$B$8) -> 300000 | Q28: =O28-P28 -> 1676692 | R28: =ROUND(הנחות!$B$9*(F28+הנחות!$B$10*G28),0) -> 2733360 | S28: =R28-Q28 -> 1056668 | T28: =RANK(S28,S$2:S$85) -> 27
A29: 1 | B29: 29 | C29: 6 | D29: 1C | E29: 3 | F29: 79.72 | G29: 13.6 | H29: 1 | J29: מזרח - דרום | K29: חלקי | L29: 80 | M29: =F29+הנחות!$B$5*G29 -> 83.8 | N29: =ROUND(M29*הנחות!$B$4,0) -> 1258844 | O29: =ROUND(N29*(1+הנחות!$B$6),0) -> 1485436 | P29: =MIN(הנחות!$B$7*O29,הנחות!$B$8) -> 297087.2 | Q29: =O29-P29 -> 1188348.8 | R29: =ROUND(הנחות!$B$9*(F29+הנחות!$B$10*G29),0) -> 2076480 | S29: =R29-Q29 -> 888131.2 | T29: =RANK(S29,S$2:S$85) -> 62
A30: 1 | B30: 30 | C30: 6 | D30: 1D | E30: 3 | F30: 78.78 | G30: 7.4 | H30: 1 | J30: דרום | L30: 80 | M30: =F30+הנחות!$B$5*G30 -> 81 | N30: =ROUND(M30*הנחות!$B$4,0) -> 1216782 | O30: =ROUND(N30*(1+הנחות!$B$6),0) -> 1435803 | P30: =MIN(הנחות!$B$7*O30,הנחות!$B$8) -> 287160.6 | Q30: =O30-P30 -> 1148642.4 | R30: =ROUND(הנחות!$B$9*(F30+הנחות!$B$10*G30),0) -> 1979520 | S30: =R30-Q30 -> 830877.6 | T30: =RANK(S30,S$2:S$85) -> 68
A31: 1 | B31: 32 | C31: 7 | D31: 1A | E31: 3 | F31: 87.77 | G31: 21.67 | H31: 2 | J31: מערב - צפון | L31: 110 | M31: =F31+הנחות!$B$5*G31 -> 94.271 | N31: =ROUND(M31*הנחות!$B$4,0) -> 1416139 | O31: =ROUND(N31*(1+הנחות!$B$6),0) -> 1671044 | P31: =MIN(הנחות!$B$7*O31,הנחות!$B$8) -> 300000 | Q31: =O31-P31 -> 1371044 | R31: =ROUND(הנחות!$B$9*(F31+הנחות!$B$10*G31),0) -> 2366520 | S31: =R31-Q31 -> 995476 | T31: =RANK(S31,S$2:S$85) -> 40
A32: 1 | B32: 33 | C32: 7 | D32: 1B | E32: 4 | F32: 107.95 | G32: 11.88 | H32: 1 | J32: מזרח - צפון | K32: חלקי | L32: 110 | M32: =F32+הנחות!$B$5*G32 -> 111.514 | N32: =ROUND(M32*הנחות!$B$4,0) -> 1675163 | O32: =ROUND(N32*(1+הנחות!$B$6),0) -> 1976692 | P32: =MIN(הנחות!$B$7*O32,הנחות!$B$8) -> 300000 | Q32: =O32-P32 -> 1676692 | R32: =ROUND(הנחות!$B$9*(F32+הנחות!$B$10*G32),0) -> 2733360 | S32: =R32-Q32 -> 1056668 | T32: =RANK(S32,S$2:S$85) -> 27
A33: 2 | B33: 1 | C33: 1 | D33: 2A | E33: 4 | F33: 107.49 | G33: 11.89 | H33: 1 | J33: מערב - צפון | L33: 110 | M33: =F33+הנחות!$B$5*G33 -> 111.057 | N33: =ROUND(M33*הנחות!$B$4,0) -> 1668298 | O33: =ROUND(N33*(1+הנחות!$B$6),0) -> 1968592 | P33: =MIN(הנחות!$B$7*O33,הנחות!$B$8) -> 300000 | Q33: =O33-P33 -> 1668592 | R33: =ROUND(הנחות!$B$9*(F33+הנחות!$B$10*G33),0) -> 2722440 | S33: =R33-Q33 -> 1053848 | T33: =RANK(S33,S$2:S$85) -> 34
A34: 2 | B34: 2 | C34: 1 | D34: 2B | E34: 3 | F34: 87.66 | G34: 21.75 | H34: 2 | J34: מזרח - צפון | K34: כן | L34: 110 | M34: =F34+הנחות!$B$5*G34 -> 94.185 | N34: =ROUND(M34*הנחות!$B$4,0) -> 1414847 | O34: =ROUND(N34*(1+הנחות!$B$6),0) -> 1669519 | P34: =MIN(הנחות!$B$7*O34,הנחות!$B$8) -> 300000 | Q34: =O34-P34 -> 1369519 | R34: =ROUND(הנחות!$B$9*(F34+הנחות!$B$10*G34),0) -> 2364840 | S34: =R34-Q34 -> 995321 | T34: =RANK(S34,S$2:S$85) -> 47
A35: 2 | B35: 3 | C35: 1 | D35: 2C | E35: 4 | F35: 109.62 | G35: 12.91 | H35: 1 | J35: מזרח - דרום | K35: כן | L35: 110 | M35: =F35+הנחות!$B$5*G35 -> 113.493 | N35: =ROUND(M35*הנחות!$B$4,0) -> 1704892 | O35: =ROUND(N35*(1+הנחות!$B$6),0) -> 2011773 | P35: =MIN(הנחות!$B$7*O35,הנחות!$B$8) -> 300000 | Q35: =O35-P35 -> 1711773 | R35: =ROUND(הנחות!$B$9*(F35+הנחות!$B$10*G35),0) -> 2785800 | S35: =R35-Q35 -> 1074027 | T35: =RANK(S35,S$2:S$85) -> 12
A36: 2 | B36: 4 | C36: 1 | D36: 2D | E36: 3 | F36: 78.65 | G36: 7.35 | H36: 1 | J36: דרום | L36: 80 | M36: =F36+הנחות!$B$5*G36 -> 80.855 | N36: =ROUND(M36*הנחות!$B$4,0) -> 1214604 | O36: =ROUND(N36*(1+הנחות!$B$6),0) -> 1433233 | P36: =MIN(הנחות!$B$7*O36,הנחות!$B$8) -> 286646.6 | Q36: =O36-P36 -> 1146586.4 | R36: =ROUND(הנחות!$B$9*(F36+הנחות!$B$10*G36),0) -> 1975800 | S36: =R36-Q36 -> 829213.6 | T36: =RANK(S36,S$2:S$85) -> 79
A37: 2 | B37: 5 | C37: 1 | D37: 2E | E37: 3 | F37: 79.9 | G37: 13.83 | H37: 1 | J37: מערב - דרום | L37: 80 | M37: =F37+הנחות!$B$5*G37 -> 84.049 | N37: =ROUND(M37*הנחות!$B$4,0) -> 1262584 | O37: =ROUND(N37*(1+הנחות!$B$6),0) -> 1489849 | P37: =MIN(הנחות!$B$7*O37,הנחות!$B$8) -> 297969.8 | Q37: =O37-P37 -> 1191879.2 | R37: =ROUND(הנחות!$B$9*(F37+הנחות!$B$10*G37),0) -> 2083560 | S37: =R37-Q37 -> 891680.8 | T37: =RANK(S37,S$2:S$85) -> 53
A38: 2 | B38: 6 | C38: 2 | D38: 2A | E38: 4 | F38: 107.49 | G38: 11.89 | H38: 1 | J38: מערב - צפון | L38: 110 | M38: =F38+הנחות!$B$5*G38 -> 111.057 | N38: =ROUND(M38*הנחות!$B$4,0) -> 1668298 | O38: =ROUND(N38*(1+הנחות!$B$6),0) -> 1968592 | P38: =MIN(הנחות!$B$7*O38,הנחות!$B$8) -> 300000 | Q38: =O38-P38 -> 1668592 | R38: =ROUND(הנחות!$B$9*(F38+הנחות!$B$10*G38),0) -> 2722440 | S38: =R38-Q38 -> 1053848 | T38: =RANK(S38,S$2:S$85) -> 34
A39: 2 | B39: 7 | C39: 2 | D39: 2B | E39: 3 | F39: 87.66 | G39: 21.75 | H39: 2 | J39: מזרח - צפון | K39: כן | L39: 110 | M39: =F39+הנחות!$B$5*G39 -> 94.185 | N39: =ROUND(M39*הנחות!$B$4,0) -> 1414847 | O39: =ROUND(N39*(1+הנחות!$B$6),0) -> 1669519 | P39: =MIN(הנחות!$B$7*O39,הנחות!$B$8) -> 300000 | Q39: =O39-P39 -> 1369519 | R39: =ROUND(הנחות!$B$9*(F39+הנחות!$B$10*G39),0) -> 2364840 | S39: =R39-Q39 -> 995321 | T39: =RANK(S39,S$2:S$85) -> 47
A40: 2 | B40: 8 | C40: 2 | D40: 2C | E40: 4 | F40: 109.62 | G40: 12.91 | H40: 1 | J40: מזרח - דרום | K40: כן | L40: 110 | M40: =F40+הנחות!$B$5*G40 -> 113.493 | N40: =ROUND(M40*הנחות!$B$4,0) -> 1704892 | O40: =ROUND(N40*(1+הנחות!$B$6),0) -> 2011773 | P40: =MIN(הנחות!$B$7*O40,הנחות!$B$8) -> 300000 | Q40: =O40-P40 -> 1711773 | R40: =ROUND(הנחות!$B$9*(F40+הנחות!$B$10*G40),0) -> 2785800 | S40: =R40-Q40 -> 1074027 | T40: =RANK(S40,S$2:S$85) -> 12
...

Sheet כל הדירות בפרויקט
A1: בניין | B1: דירה | C1: קומה | D1: טיפוס | E1: חדרים | F1: שטח דירה (מ"ר) | G1: מרפסת שמש (מ"ר) | H1: מס' מרפסות | I1: חצר | J1: כיווני אוויר | K1: פונה לפארק | L1: תקרת מחיר מטרה (מ"ר) | M1: מחיר מטרה
A2: 1 | B2: 1 | C2: 0 | D2: 1G | E2: 4 | F2: 160.7 | I2: כן | J2: מזרח - דרום | K2: חלקי
A3: 1 | B3: 2 | C3: 1 | D3: 1A | E3: 3 | F3: 87.77 | G3: 21.67 | H3: 2 | J3: מערב - צפון | L3: 110 | M3: כן
A4: 1 | B4: 3 | C4: 1 | D4: 1B | E4: 4 | F4: 107.95 | G4: 11.88 | H4: 1 | J4: מזרח - צפון | K4: חלקי | L4: 110 | M4: כן
A5: 1 | B5: 4 | C5: 1 | D5: 1C | E5: 3 | F5: 79.72 | G5: 13.6 | H5: 1 | J5: מזרח - דרום | K5: חלקי | L5: 80 | M5: כן
A6: 1 | B6: 5 | C6: 1 | D6: 1D | E6: 3 | F6: 78.78 | G6: 7.4 | H6: 1 | J6: דרום | L6: 80 | M6: כן
A7: 1 | B7: 6 | C7: 1 | D7: 1E | E7: 4 | F7: 109.6 | G7: 13.01 | H7: 1 | J7: מערב - דרום | L7: 110 | M7: כן
A8: 1 | B8: 7 | C8: 2 | D8: 1A | E8: 3 | F8: 87.77 | G8: 21.67 | H8: 2 | J8: מערב - צפון | L8: 110 | M8: כן
A9: 1 | B9: 8 | C9: 2 | D9: 1B | E9: 4 | F9: 107.95 | G9: 11.88 | H9: 1 | J9: מזרח - צפון | K9: חלקי | L9: 110 | M9: כן
A10: 1 | B10: 9 | C10: 2 | D10: 1C | E10: 3 | F10: 79.72 | G10: 13.6 | H10: 1 | J10: מזרח - דרום | K10: חלקי | L10: 80 | M10: כן
A11: 1 | B11: 10 | C11: 2 | D11: 1D | E11: 3 | F11: 78.78 | G11: 7.4 | H11: 1 | J11: דרום | L11: 80 | M11: כן
A12: 1 | B12: 11 | C12: 2 | D12: 1E | E12: 4 | F12: 109.6 | G12: 13.01 | H12: 1 | J12: מערב - דרום | L12: 110 | M12: כן
A13: 1 | B13: 12 | C13: 3 | D13: 1A | E13: 3 | F13: 87.77 | G13: 21.67 | H13: 2 | J13: מערב - צפון | L13: 110 | M13: כן
A14: 1 | B14: 13 | C14: 3 | D14: 1B | E14: 4 | F14: 107.95 | G14: 11.88 | H14: 1 | J14: מזרח - צפון | K14: חלקי | L14: 110 | M14: כן
A15: 1 | B15: 14 | C15: 3 | D15: 1C | E15: 3 | F15: 79.72 | G15: 13.6 | H15: 1 | J15: מזרח - דרום | K15: חלקי | L15: 80 | M15: כן
A16: 1 | B16: 15 | C16: 3 | D16: 1D | E16: 3 | F16: 78.78 | G16: 7.4 | H16: 1 | J16: דרום | L16: 80 | M16: כן
A17: 1 | B17: 16 | C17: 3 | D17: 1E | E17: 4 | F17: 109.6 | G17: 13.01 | H17: 1 | J17: מערב - דרום | L17: 110 | M17: כן
A18: 1 | B18: 17 | C18: 4 | D18: 1A | E18: 3 | F18: 87.77 | G18: 21.67 | H18: 2 | J18: מערב - צפון | L18: 110 | M18: כן
A19: 1 | B19: 18 | C19: 4 | D19: 1B | E19: 4 | F19: 107.95 | G19: 11.88 | H19: 1 | J19: מזרח - צפון | K19: חלקי | L19: 110 | M19: כן
A20: 1 | B20: 19 | C20: 4 | D20: 1C | E20: 3 | F20: 79.72 | G20: 13.6 | H20: 1 | J20: מזרח - דרום | K20: חלקי | L20: 80 | M20: כן
A21: 1 | B21: 20 | C21: 4 | D21: 1D | E21: 3 | F21: 78.78 | G21: 7.4 | H21: 1 | J21: דרום | L21: 80 | M21: כן
A22: 1 | B22: 21 | C22: 4 | D22: 1E | E22: 4 | F22: 109.6 | G22: 13.01 | H22: 1 | J22: מערב - דרום | L22: 110 | M22: כן
A23: 1 | B23: 22 | C23: 5 | D23: 1A | E23: 3 | F23: 87.77 | G23: 21.67 | H23: 2 | J23: מערב - צפון | L23: 110 | M23: כן
A24: 1 | B24: 23 | C24: 5 | D24: 1B | E24: 4 | F24: 107.95 | G24: 11.88 | H24: 1 | J24: מזרח - צפון | K24: חלקי | L24: 110 | M24: כן
A25: 1 | B25: 24 | C25: 5 | D25: 1C | E25: 3 | F25: 79.72 | G25: 13.6 | H25: 1 | J25: מזרח - דרום | K25: חלקי | L25: 80 | M25: כן
A26: 1 | B26: 25 | C26: 5 | D26: 1D | E26: 3 | F26: 78.78 | G26: 7.4 | H26: 1 | J26: דרום | L26: 80 | M26: כן
A27: 1 | B27: 26 | C27: 5 | D27: 1E | E27: 4 | F27: 109.6 | G27: 13.01 | H27: 1 | J27: מערב - דרום | L27: 110 | M27: כן
A28: 1 | B28: 27 | C28: 6 | D28: 1A | E28: 3 | F28: 87.77 | G28: 21.67 | H28: 2 | J28: מערב - צפון | L28: 110 | M28: כן
A29: 1 | B29: 28 | C29: 6 | D29: 1B | E29: 4 | F29: 107.95 | G29: 11.88 | H29: 1 | J29: מזרח - צפון | K29: חלקי | L29: 110 | M29: כן
A30: 1 | B30: 29 | C30: 6 | D30: 1C | E30: 3 | F30: 79.72 | G30: 13.6 | H30: 1 | J30: מזרח - דרום | K30: חלקי | L30: 80 | M30: כן
A31: 1 | B31: 30 | C31: 6 | D31: 1D | E31: 3 | F31: 78.78 | G31: 7.4 | H31: 1 | J31: דרום | L31: 80 | M31: כן
A32: 1 | B32: 31 | C32: 6 | D32: 1E | E32: 4 | F32: 109.6 | G32: 13.01 | H32: 1 | J32: מערב - דרום
A33: 1 | B33: 32 | C33: 7 | D33: 1A | E33: 3 | F33: 87.77 | G33: 21.67 | H33: 2 | J33: מערב - צפון | L33: 110 | M33: כן
A34: 1 | B34: 33 | C34: 7 | D34: 1B | E34: 4 | F34: 107.95 | G34: 11.88 | H34: 1 | J34: מזרח - צפון | K34: חלקי | L34: 110 | M34: כן
A35: 1 | B35: 34 | C35: 7 | D35: 1H | E35: 5 | F35: 131.06 | G35: 13.63 | H35: 1 | J35: מזרח - דרום | K35: חלקי
A36: 1 | B36: 35 | C36: 7 | D36: 1I | E36: 5 | F36: 143.31 | G36: 17.36 | H36: 2 | J36: מערב - דרום
A37: 1 | B37: 36 | C37: 8 | D37: 1P | E37: 4 | F37: 160.46 | G37: 4.46 | H37: 1 | J37: מערב - דרום - צפון
A38: 1 | B38: 37 | C38: 8 | D38: 1P | E38: 5 | F38: 158.9 | G38: 4.46 | H38: 1 | J38: מזרח - דרום - צפון | K38: חלקי
A39: 2 | B39: 1 | C39: 1 | D39: 2A | E39: 4 | F39: 107.49 | G39: 11.89 | H39: 1 | J39: מערב - צפון | L39: 110 | M39: כן
A40: 2 | B40: 2 | C40: 1 | D40: 2B | E40: 3 | F40: 87.66 | G40: 21.75 | H40: 2 | J40: מזרח - צפון | K40: כן | L40: 110 | M40: כן
...
